2025-01-01 00:49:25,386 - ERROR - Bejelentkezési hiba: 'EnhancedAuthManager' object has no attribute '_update_last_login'
2025-01-01 12:07:58,082 - ERROR - Hiba: 'DatabaseHandler' object has no attribute 'conn'
Traceback (most recent call last):
  File "E:\fuvarok_projekt\run.py", line 16, in <module>
    window = FuvarAdminApp()
             ^^^^^^^^^^^^^^^
  File "E:\fuvarok_projekt\modified_main.py", line 38, in __init__
    self.initManagers()
  File "E:\fuvarok_projekt\modified_main.py", line 71, in initManagers
    self.database_manager = DatabaseManager(self)
                            ^^^^^^^^^^^^^^^^^^^^^
  File "E:\fuvarok_projekt\database_manager.py", line 28, in __init__
    self.setupDatabase()
  File "E:\fuvarok_projekt\database_manager.py", line 46, in setupDatabase
    cursor = self.db.conn.cursor()
             ^^^^^^^^^^^^
AttributeError: 'DatabaseHandler' object has no attribute 'conn'
2025-01-01 12:11:27,661 - ERROR - Hiba: '_GeneratorContextManager' object has no attribute 'close'
Traceback (most recent call last):
  File "E:\fuvarok_projekt\database_handler.py", line 41, in execute_query
    cursor = conn.cursor()
             ^^^^^^^^^^^
AttributeError: '_GeneratorContextManager' object has no attribute 'cursor'

During handling of the above exception, another exception occurred:

Traceback (most recent call last):
  File "E:\fuvarok_projekt\database_handler.py", line 48, in execute_query
    conn.rollback()
    ^^^^^^^^^^^^^
AttributeError: '_GeneratorContextManager' object has no attribute 'rollback'

During handling of the above exception, another exception occurred:

Traceback (most recent call last):
  File "E:\fuvarok_projekt\run.py", line 16, in <module>
    window = FuvarAdminApp()
             ^^^^^^^^^^^^^^^
  File "E:\fuvarok_projekt\modified_main.py", line 31, in __init__
    self.auth_manager = EnhancedAuthManager(self.db)  # Az új EnhancedAuthManager használata
                       ^^^^^^^^^^^^^^^^^^^^^^^^^^^^
  File "E:\fuvarok_projekt\security\enhanced_auth.py", line 17, in __init__
    self._setup_auth_table()
  File "E:\fuvarok_projekt\security\enhanced_auth.py", line 45, in _setup_auth_table
    self.db.execute_query(query)
  File "E:\fuvarok_projekt\database_handler.py", line 53, in execute_query
    conn.close()
    ^^^^^^^^^^
AttributeError: '_GeneratorContextManager' object has no attribute 'close'
2025-01-01 12:13:31,663 - ERROR - Hiba: '_GeneratorContextManager' object has no attribute 'close'
Traceback (most recent call last):
  File "E:\fuvarok_projekt\database_handler.py", line 41, in execute_query
    cursor = conn.cursor()
             ^^^^^^^^^^^
AttributeError: '_GeneratorContextManager' object has no attribute 'cursor'

During handling of the above exception, another exception occurred:

Traceback (most recent call last):
  File "E:\fuvarok_projekt\database_handler.py", line 48, in execute_query
    conn.rollback()
    ^^^^^^^^^^^^^
AttributeError: '_GeneratorContextManager' object has no attribute 'rollback'

During handling of the above exception, another exception occurred:

Traceback (most recent call last):
  File "E:\fuvarok_projekt\run.py", line 16, in <module>
    window = FuvarAdminApp()
             ^^^^^^^^^^^^^^^
  File "E:\fuvarok_projekt\modified_main.py", line 31, in __init__
    self.auth_manager = EnhancedAuthManager(self.db)  # Az új EnhancedAuthManager használata
                       ^^^^^^^^^^^^^^^^^^^^^^^^^^^^
  File "E:\fuvarok_projekt\security\enhanced_auth.py", line 17, in __init__
    self._setup_auth_table()
  File "E:\fuvarok_projekt\security\enhanced_auth.py", line 45, in _setup_auth_table
    self.db.execute_query(query)
  File "E:\fuvarok_projekt\database_handler.py", line 53, in execute_query
    conn.close()
    ^^^^^^^^^^
AttributeError: '_GeneratorContextManager' object has no attribute 'close'
2025-01-01 12:17:38,294 - ERROR - Hiba: '_GeneratorContextManager' object has no attribute 'close'
Traceback (most recent call last):
  File "E:\fuvarok_projekt\database_handler.py", line 41, in execute_query
    cursor = conn.cursor()
             ^^^^^^^^^^^
AttributeError: '_GeneratorContextManager' object has no attribute 'cursor'

During handling of the above exception, another exception occurred:

Traceback (most recent call last):
  File "E:\fuvarok_projekt\database_handler.py", line 48, in execute_query
    conn.rollback()
    ^^^^^^^^^^^^^
AttributeError: '_GeneratorContextManager' object has no attribute 'rollback'

During handling of the above exception, another exception occurred:

Traceback (most recent call last):
  File "E:\fuvarok_projekt\run.py", line 16, in <module>
    window = FuvarAdminApp()
             ^^^^^^^^^^^^^^^
  File "E:\fuvarok_projekt\modified_main.py", line 31, in __init__
    self.auth_manager = EnhancedAuthManager(self.db)  # Az új EnhancedAuthManager használata
                       ^^^^^^^^^^^^^^^^^^^^^^^^^^^^
  File "E:\fuvarok_projekt\security\enhanced_auth.py", line 17, in __init__
    self._setup_auth_table()
  File "E:\fuvarok_projekt\security\enhanced_auth.py", line 45, in _setup_auth_table
    self.db.execute_query(query)
  File "E:\fuvarok_projekt\database_handler.py", line 53, in execute_query
    conn.close()
    ^^^^^^^^^^
AttributeError: '_GeneratorContextManager' object has no attribute 'close'
2025-01-01 12:22:32,428 - ERROR - Hiba: '_GeneratorContextManager' object has no attribute 'close'
Traceback (most recent call last):
  File "E:\fuvarok_projekt\database_handler.py", line 41, in execute_query
    cursor = conn.cursor()
             ^^^^^^^^^^^
AttributeError: '_GeneratorContextManager' object has no attribute 'cursor'

During handling of the above exception, another exception occurred:

Traceback (most recent call last):
  File "E:\fuvarok_projekt\database_handler.py", line 48, in execute_query
    conn.rollback()
    ^^^^^^^^^^^^^
AttributeError: '_GeneratorContextManager' object has no attribute 'rollback'

During handling of the above exception, another exception occurred:

Traceback (most recent call last):
  File "E:\fuvarok_projekt\run.py", line 16, in <module>
    window = FuvarAdminApp()
             ^^^^^^^^^^^^^^^
  File "E:\fuvarok_projekt\modified_main.py", line 31, in __init__
    self.auth_manager = EnhancedAuthManager(self.db)  # Az új EnhancedAuthManager használata
                       ^^^^^^^^^^^^^^^^^^^^^^^^^^^^
  File "E:\fuvarok_projekt\security\enhanced_auth.py", line 17, in __init__
    self._setup_auth_table()
  File "E:\fuvarok_projekt\security\enhanced_auth.py", line 45, in _setup_auth_table
    self.db.execute_query(query)
  File "E:\fuvarok_projekt\database_handler.py", line 53, in execute_query
    conn.close()
    ^^^^^^^^^^
AttributeError: '_GeneratorContextManager' object has no attribute 'close'
2025-01-01 12:33:34,837 - ERROR - Hiba: '_GeneratorContextManager' object has no attribute 'close'
Traceback (most recent call last):
  File "E:\fuvarok_projekt\database_handler.py", line 41, in execute_query
    cursor = conn.cursor()
             ^^^^^^^^^^^
AttributeError: '_GeneratorContextManager' object has no attribute 'cursor'

During handling of the above exception, another exception occurred:

Traceback (most recent call last):
  File "E:\fuvarok_projekt\database_handler.py", line 48, in execute_query
    conn.rollback()
    ^^^^^^^^^^^^^
AttributeError: '_GeneratorContextManager' object has no attribute 'rollback'

During handling of the above exception, another exception occurred:

Traceback (most recent call last):
  File "E:\fuvarok_projekt\run.py", line 16, in <module>
    window = FuvarAdminApp()
             ^^^^^^^^^^^^^^^
  File "E:\fuvarok_projekt\modified_main.py", line 31, in __init__
    self.auth_manager = EnhancedAuthManager(self.db)  # Az új EnhancedAuthManager használata
                       ^^^^^^^^^^^^^^^^^^^^^^^^^^^^
  File "E:\fuvarok_projekt\security\enhanced_auth.py", line 17, in __init__
    self._setup_auth_table()
  File "E:\fuvarok_projekt\security\enhanced_auth.py", line 45, in _setup_auth_table
    self.db.execute_query(query)
  File "E:\fuvarok_projekt\database_handler.py", line 53, in execute_query
    conn.close()
    ^^^^^^^^^^
AttributeError: '_GeneratorContextManager' object has no attribute 'close'
2025-01-01 12:39:33,155 - ERROR - Hiba: 'DatabaseHandler' object has no attribute 'conn'
Traceback (most recent call last):
  File "E:\fuvarok_projekt\run.py", line 16, in <module>
    window = FuvarAdminApp()
             ^^^^^^^^^^^^^^^
  File "E:\fuvarok_projekt\modified_main.py", line 38, in __init__
    self.initManagers()
  File "E:\fuvarok_projekt\modified_main.py", line 71, in initManagers
    self.database_manager = DatabaseManager(self)
                            ^^^^^^^^^^^^^^^^^^^^^
  File "E:\fuvarok_projekt\database_manager.py", line 28, in __init__
    self.setupDatabase()
  File "E:\fuvarok_projekt\database_manager.py", line 46, in setupDatabase
    cursor = self.db.conn.cursor()
             ^^^^^^^^^^^^
AttributeError: 'DatabaseHandler' object has no attribute 'conn'
2025-01-01 12:42:24,802 - ERROR - Hiba: 'DatabaseHandler' object has no attribute 'conn'
Traceback (most recent call last):
  File "E:\fuvarok_projekt\run.py", line 16, in <module>
    window = FuvarAdminApp()
             ^^^^^^^^^^^^^^^
  File "E:\fuvarok_projekt\modified_main.py", line 38, in __init__
    self.initManagers()
  File "E:\fuvarok_projekt\modified_main.py", line 71, in initManagers
    self.database_manager = DatabaseManager(self)
                            ^^^^^^^^^^^^^^^^^^^^^
  File "E:\fuvarok_projekt\database_manager.py", line 28, in __init__
    self.setupDatabase()
  File "E:\fuvarok_projekt\database_manager.py", line 46, in setupDatabase
    cursor = self.db.conn.cursor()
             ^^^^^^^^^^^^
AttributeError: 'DatabaseHandler' object has no attribute 'conn'
2025-01-01 13:33:22,124 - ERROR - Beszúrási hiba: 'DatabaseHandler' object has no attribute 'get_connection'
2025-01-01 13:33:22,124 - ERROR - Audit log hiba: 'DatabaseHandler' object has no attribute 'get_connection'
2025-01-01 13:34:03,664 - ERROR - Beszúrási hiba: 'DatabaseHandler' object has no attribute 'get_connection'
2025-01-01 13:46:00,027 - ERROR - Beszúrási hiba: 'DatabaseHandler' object has no attribute 'get_connection'
2025-01-01 13:46:00,028 - ERROR - Audit log hiba: 'DatabaseHandler' object has no attribute 'get_connection'
2025-01-01 13:51:43,495 - ERROR - Beszúrási hiba: 'DatabaseHandler' object has no attribute 'get_connection'
2025-01-01 13:51:43,495 - ERROR - Audit log hiba: 'DatabaseHandler' object has no attribute 'get_connection'
2025-01-01 14:00:28,676 - ERROR - Beszúrási hiba: 'DatabaseHandler' object has no attribute 'get_connection'
2025-01-01 14:00:28,676 - ERROR - Audit log hiba: 'DatabaseHandler' object has no attribute 'get_connection'
2025-01-01 14:00:38,496 - ERROR - Hiba: 'FuvarAdminApp' object has no attribute 'address_input'
Traceback (most recent call last):
  File "E:\fuvarok_projekt\run.py", line 16, in <module>
    window = FuvarAdminApp()
             ^^^^^^^^^^^^^^^
  File "E:\fuvarok_projekt\modified_main.py", line 36, in __init__
    self.initUI()
  File "E:\fuvarok_projekt\modified_main.py", line 85, in initUI
    top_frame = self.ui_manager.createTopFrame()
                ^^^^^^^^^^^^^^^^^^^^^^^^^^^^^^^^
  File "E:\fuvarok_projekt\ui_manager.py", line 93, in createTopFrame
    right_panel = self.createRightPanel()
                  ^^^^^^^^^^^^^^^^^^^^^^^
  File "E:\fuvarok_projekt\ui_manager.py", line 175, in createRightPanel
    layout.addLayout(self.createInputGroup("Cím:", self.parent.address_input))
                                                   ^^^^^^^^^^^^^^^^^^^^^^^^^
AttributeError: 'FuvarAdminApp' object has no attribute 'address_input'
2025-01-01 14:03:35,672 - ERROR - Beszúrási hiba: 'DatabaseHandler' object has no attribute 'get_connection'
2025-01-01 14:03:35,672 - ERROR - Audit log hiba: 'DatabaseHandler' object has no attribute 'get_connection'
2025-01-01 14:04:27,552 - ERROR - Beszúrási hiba: 'DatabaseHandler' object has no attribute 'get_connection'
2025-01-01 18:40:51,016 - ERROR - Beszúrási hiba: 'DatabaseHandler' object has no attribute 'get_connection'
2025-01-01 18:40:51,031 - ERROR - Audit log hiba: 'DatabaseHandler' object has no attribute 'get_connection'
2025-01-01 18:50:01,926 - ERROR - Beszúrási hiba: 'DatabaseHandler' object has no attribute 'get_connection'
2025-01-01 18:50:01,926 - ERROR - Audit log hiba: 'DatabaseHandler' object has no attribute 'get_connection'
2025-01-01 19:03:48,764 - ERROR - Beszúrási hiba: 'DatabaseHandler' object has no attribute 'get_connection'
2025-01-01 19:03:48,765 - ERROR - Audit log hiba: 'DatabaseHandler' object has no attribute 'get_connection'
2025-01-01 19:56:57,326 - ERROR - Beszúrási hiba: 'DatabaseHandler' object has no attribute 'get_connection'
2025-01-01 19:56:57,326 - ERROR - Audit log hiba: 'DatabaseHandler' object has no attribute 'get_connection'
2025-01-01 19:57:11,598 - ERROR - Hiba: 'FuvarAdminApp' object has no attribute 'loadFactories'
Traceback (most recent call last):
  File "E:\fuvarok_projekt\run.py", line 16, in <module>
    window = FuvarAdminApp()
             ^^^^^^^^^^^^^^^
  File "E:\fuvarok_projekt\modified_main.py", line 38, in __init__
    self.loadInitialData()
  File "E:\fuvarok_projekt\modified_main.py", line 143, in loadInitialData
    self.loadFactories()
    ^^^^^^^^^^^^^^^^^^
AttributeError: 'FuvarAdminApp' object has no attribute 'loadFactories'
2025-01-01 20:19:22,161 - ERROR - Beszúrási hiba: 'DatabaseHandler' object has no attribute 'get_connection'
2025-01-01 20:19:22,161 - ERROR - Audit log hiba: 'DatabaseHandler' object has no attribute 'get_connection'
2025-01-01 20:19:22,170 - ERROR - Hiba: 'DatabaseManager' object has no attribute 'onFactorySelected'
Traceback (most recent call last):
  File "E:\fuvarok_projekt\run.py", line 16, in <module>
    window = FuvarAdminApp()
             ^^^^^^^^^^^^^^^
  File "E:\fuvarok_projekt\modified_main.py", line 35, in __init__
    self.initManagers()
  File "E:\fuvarok_projekt\modified_main.py", line 68, in initManagers
    self.database_manager = DatabaseManager(self)
                            ^^^^^^^^^^^^^^^^^^^^^
  File "E:\fuvarok_projekt\database_manager.py", line 29, in __init__
    self.initUI()
  File "E:\fuvarok_projekt\database_manager.py", line 196, in initUI
    tabs.addTab(self.createFactoriesTab(), "Gyárak")
                ^^^^^^^^^^^^^^^^^^^^^^^^^
  File "E:\fuvarok_projekt\database_manager.py", line 794, in createFactoriesTab
    self.factory_table.itemClicked.connect(self.onFactorySelected)
                                           ^^^^^^^^^^^^^^^^^^^^^^
AttributeError: 'DatabaseManager' object has no attribute 'onFactorySelected'. Did you mean: 'onDriverSelected'?
2025-01-01 20:32:40,009 - ERROR - Beszúrási hiba: 'DatabaseHandler' object has no attribute 'get_connection'
2025-01-01 20:32:40,009 - ERROR - Audit log hiba: 'DatabaseHandler' object has no attribute 'get_connection'
2025-01-01 20:32:40,018 - ERROR - Hiba: 'DatabaseManager' object has no attribute 'onFactorySelected'
Traceback (most recent call last):
  File "E:\fuvarok_projekt\run.py", line 16, in <module>
    window = FuvarAdminApp()
             ^^^^^^^^^^^^^^^
  File "E:\fuvarok_projekt\modified_main.py", line 35, in __init__
    self.initManagers()
  File "E:\fuvarok_projekt\modified_main.py", line 68, in initManagers
    self.database_manager = DatabaseManager(self)
                            ^^^^^^^^^^^^^^^^^^^^^
  File "E:\fuvarok_projekt\database_manager.py", line 29, in __init__
    self.initUI()
  File "E:\fuvarok_projekt\database_manager.py", line 196, in initUI
    tabs.addTab(self.createFactoriesTab(), "Gyárak")
                ^^^^^^^^^^^^^^^^^^^^^^^^^
  File "E:\fuvarok_projekt\database_manager.py", line 794, in createFactoriesTab
    self.factory_table.itemClicked.connect(self.onFactorySelected)
                                           ^^^^^^^^^^^^^^^^^^^^^^
AttributeError: 'DatabaseManager' object has no attribute 'onFactorySelected'. Did you mean: 'onDriverSelected'?
2025-01-01 20:34:31,477 - ERROR - Beszúrási hiba: 'DatabaseHandler' object has no attribute 'get_connection'
2025-01-01 20:34:31,477 - ERROR - Audit log hiba: 'DatabaseHandler' object has no attribute 'get_connection'
2025-01-01 20:34:31,534 - ERROR - Hiba: 'FuvarAdminApp' object has no attribute 'loadFactories'
Traceback (most recent call last):
  File "E:\fuvarok_projekt\run.py", line 16, in <module>
    window = FuvarAdminApp()
             ^^^^^^^^^^^^^^^
  File "E:\fuvarok_projekt\modified_main.py", line 38, in __init__
    self.loadInitialData()
  File "E:\fuvarok_projekt\modified_main.py", line 143, in loadInitialData
    self.loadFactories()
    ^^^^^^^^^^^^^^^^^^
AttributeError: 'FuvarAdminApp' object has no attribute 'loadFactories'
2025-01-01 20:41:12,959 - ERROR - Beszúrási hiba: 'DatabaseHandler' object has no attribute 'get_connection'
2025-01-01 20:41:12,959 - ERROR - Audit log hiba: 'DatabaseHandler' object has no attribute 'get_connection'
2025-01-01 20:41:39,069 - ERROR - Beszúrási hiba: 'DatabaseHandler' object has no attribute 'get_connection'
2025-01-01 20:44:17,533 - ERROR - Beszúrási hiba: 'DatabaseHandler' object has no attribute 'get_connection'
2025-01-01 20:47:00,521 - ERROR - Beszúrási hiba: 'DatabaseHandler' object has no attribute 'get_connection'
2025-01-01 20:47:00,521 - ERROR - Audit log hiba: 'DatabaseHandler' object has no attribute 'get_connection'
2025-01-01 20:47:54,439 - ERROR - Beszúrási hiba: 'DatabaseHandler' object has no attribute 'get_connection'
2025-01-01 20:51:32,436 - ERROR - Beszúrási hiba: 'DatabaseHandler' object has no attribute 'get_connection'
2025-01-01 20:51:32,436 - ERROR - Audit log hiba: 'DatabaseHandler' object has no attribute 'get_connection'
2025-01-01 20:54:06,142 - ERROR - Beszúrási hiba: 'DatabaseHandler' object has no attribute 'get_connection'
2025-01-01 20:54:06,142 - ERROR - Audit log hiba: 'DatabaseHandler' object has no attribute 'get_connection'
2025-01-01 20:54:25,366 - ERROR - Lekérdezési hiba: cannot commit transaction - SQL statements in progress
Query: INSERT INTO factories (name) VALUES (?) RETURNING id
2025-01-01 20:54:52,550 - ERROR - Beszúrási hiba: 'DatabaseHandler' object has no attribute 'get_connection'
2025-01-01 21:34:09,769 - ERROR - Beszúrási hiba: 'DatabaseHandler' object has no attribute 'get_connection'
2025-01-01 21:34:09,769 - ERROR - Audit log hiba: 'DatabaseHandler' object has no attribute 'get_connection'
2025-01-01 21:34:19,894 - ERROR - Lekérdezési hiba: cannot commit transaction - SQL statements in progress
Query: INSERT INTO factories (name) VALUES (?) RETURNING id
2025-01-01 21:34:40,776 - ERROR - Beszúrási hiba: 'DatabaseHandler' object has no attribute 'get_connection'
2025-01-01 23:17:59,726 - ERROR - Lekérdezési hiba: Cannot operate on a closed database.
Query: SELECT name FROM drivers ORDER BY name
2025-01-01 23:18:07,560 - ERROR - Lekérdezési hiba: Cannot operate on a closed database.
Query: SELECT plate_number FROM vehicles ORDER BY plate_number
2025-01-01 23:18:11,391 - ERROR - Lekérdezési hiba: Cannot operate on a closed database.
Query: SELECT * FROM factories ORDER BY name
2025-01-01 23:18:13,959 - ERROR - Lekérdezési hiba: Cannot operate on a closed database.
Query: SELECT address FROM addresses ORDER BY address
2025-01-01 23:18:31,426 - ERROR - Lekérdezési hiba: cannot commit transaction - SQL statements in progress
Query: INSERT INTO factories (name) VALUES (?) RETURNING id
2025-01-01 23:18:52,117 - ERROR - Beszúrási hiba: table vehicles has no column named type
2025-01-01 23:19:03,309 - ERROR - Lekérdezési hiba: Cannot operate on a closed database.
Query: SELECT * FROM factories ORDER BY name
2025-01-01 23:36:20,235 - ERROR - Query error: cannot commit transaction - SQL statements in progress
2025-01-02 00:07:07,075 - ERROR - Hiba: 'DatabaseHandler' object has no attribute '_conn'
Traceback (most recent call last):
  File "E:\fuvarok_projekt\database_handler.py", line 101, in execute_query
    cursor = self._conn.cursor()
             ^^^^^^^^^^
AttributeError: 'DatabaseHandler' object has no attribute '_conn'. Did you mean: 'conn'?

During handling of the above exception, another exception occurred:

Traceback (most recent call last):
  File "E:\fuvarok_projekt\run.py", line 16, in <module>
    window = FuvarAdminApp()
             ^^^^^^^^^^^^^^^
  File "E:\fuvarok_projekt\modified_main.py", line 30, in __init__
    self.auth_manager = EnhancedAuthManager(self.db)
                        ^^^^^^^^^^^^^^^^^^^^^^^^^^^^
  File "E:\fuvarok_projekt\security\enhanced_auth.py", line 17, in __init__
    self._setup_auth_table()
  File "E:\fuvarok_projekt\security\enhanced_auth.py", line 45, in _setup_auth_table
    self.db.execute_query(query)
  File "E:\fuvarok_projekt\database_handler.py", line 109, in execute_query
    self._conn.rollback()
    ^^^^^^^^^^
AttributeError: 'DatabaseHandler' object has no attribute '_conn'. Did you mean: 'conn'?
2025-01-02 00:13:28,264 - ERROR - Audit log hiba: 'DatabaseHandler' object has no attribute 'insert_record'
2025-01-02 00:14:17,901 - ERROR - Query hiba: cannot commit transaction - SQL statements in progress
2025-01-02 00:16:51,608 - INFO - users tábla létrehozva/ellenõrizve
2025-01-02 00:16:51,609 - INFO - drivers tábla létrehozva/ellenõrizve
2025-01-02 00:16:51,609 - INFO - vehicles tábla létrehozva/ellenõrizve
2025-01-02 00:16:51,609 - INFO - factories tábla létrehozva/ellenõrizve
2025-01-02 00:16:51,609 - INFO - addresses tábla létrehozva/ellenõrizve
2025-01-02 00:17:02,626 - INFO - users tábla létrehozva/ellenõrizve
2025-01-02 00:17:02,626 - INFO - drivers tábla létrehozva/ellenõrizve
2025-01-02 00:17:02,626 - INFO - vehicles tábla létrehozva/ellenõrizve
2025-01-02 00:17:02,626 - INFO - factories tábla létrehozva/ellenõrizve
2025-01-02 00:17:02,626 - INFO - addresses tábla létrehozva/ellenõrizve
2025-01-02 00:17:09,138 - INFO - users tábla létrehozva/ellenõrizve
2025-01-02 00:17:09,138 - INFO - drivers tábla létrehozva/ellenõrizve
2025-01-02 00:17:09,138 - INFO - vehicles tábla létrehozva/ellenõrizve
2025-01-02 00:17:09,138 - INFO - factories tábla létrehozva/ellenõrizve
2025-01-02 00:17:09,138 - INFO - addresses tábla létrehozva/ellenõrizve
2025-01-02 00:17:23,825 - INFO - users tábla létrehozva/ellenõrizve
2025-01-02 00:17:23,825 - INFO - drivers tábla létrehozva/ellenõrizve
2025-01-02 00:17:23,825 - INFO - vehicles tábla létrehozva/ellenõrizve
2025-01-02 00:17:23,825 - INFO - factories tábla létrehozva/ellenõrizve
2025-01-02 00:17:23,825 - INFO - addresses tábla létrehozva/ellenõrizve
2025-01-02 00:17:29,383 - ERROR - Query hiba: cannot commit transaction - SQL statements in progress
2025-01-02 00:17:49,860 - ERROR - Beszúrási hiba: table vehicles has no column named type
2025-01-02 00:20:28,403 - ERROR - Beszúrási hiba: table users has no column named password_changed_at
2025-01-02 00:20:28,403 - ERROR - Regisztrációs hiba: table users has no column named password_changed_at
2025-01-02 00:20:38,055 - ERROR - Query hiba: no such column: locked_until
Query: SELECT locked_until FROM users WHERE username = ?
2025-01-02 00:20:38,055 - ERROR - Bejelentkezési hiba: no such column: locked_until
2025-01-02 00:20:48,753 - ERROR - Query hiba: no such column: locked_until
Query: SELECT locked_until FROM users WHERE username = ?
2025-01-02 00:20:48,753 - ERROR - Bejelentkezési hiba: no such column: locked_until
2025-01-02 00:21:05,833 - ERROR - Query hiba: no such column: locked_until
Query: SELECT locked_until FROM users WHERE username = ?
2025-01-02 00:21:05,833 - ERROR - Bejelentkezési hiba: no such column: locked_until
2025-01-02 00:27:09,253 - ERROR - Bejelentkezési hiba: Invalid salt
2025-01-02 09:44:13,839 - ERROR - Bejelentkezési hiba: Invalid salt
2025-01-02 09:52:41,017 - ERROR - Bejelentkezési hiba: Invalid salt
2025-01-02 09:54:50,179 - ERROR - Bejelentkezési hiba: Invalid salt
2025-01-02 09:55:22,090 - ERROR - Hiba: 'DatabaseHandler' object has no attribute '_conn'
Traceback (most recent call last):
  File "E:\fuvarok_projekt\database_handler.py", line 101, in execute_query
    cursor = self._conn.cursor()
             ^^^^^^^^^^
AttributeError: 'DatabaseHandler' object has no attribute '_conn'. Did you mean: 'conn'?

During handling of the above exception, another exception occurred:

Traceback (most recent call last):
  File "E:\fuvarok_projekt\run.py", line 16, in <module>
    window = FuvarAdminApp()
             ^^^^^^^^^^^^^^^
  File "E:\fuvarok_projekt\modified_main.py", line 30, in __init__
    self.auth_manager = EnhancedAuthManager(self.db)
                        ^^^^^^^^^^^^^^^^^^^^^^^^^^^^
  File "E:\fuvarok_projekt\security\enhanced_auth.py", line 17, in __init__
    self._setup_auth_table()
  File "E:\fuvarok_projekt\security\enhanced_auth.py", line 44, in _setup_auth_table
    self.db.execute_query(query)
  File "E:\fuvarok_projekt\database_handler.py", line 109, in execute_query
    self._conn.rollback()
    ^^^^^^^^^^
AttributeError: 'DatabaseHandler' object has no attribute '_conn'. Did you mean: 'conn'?
2025-01-02 10:15:56,385 - ERROR - Hiba: 'DatabaseHandler' object has no attribute '_conn'
Traceback (most recent call last):
  File "E:\fuvarok_projekt\database_handler.py", line 101, in execute_query
    cursor = self._conn.cursor()
             ^^^^^^^^^^
AttributeError: 'DatabaseHandler' object has no attribute '_conn'. Did you mean: 'conn'?

During handling of the above exception, another exception occurred:

Traceback (most recent call last):
  File "E:\fuvarok_projekt\run.py", line 16, in <module>
    window = FuvarAdminApp()
             ^^^^^^^^^^^^^^^
  File "E:\fuvarok_projekt\modified_main.py", line 30, in __init__
    self.auth_manager = EnhancedAuthManager(self.db)
                        ^^^^^^^^^^^^^^^^^^^^^^^^^^^^
  File "E:\fuvarok_projekt\security\enhanced_auth.py", line 17, in __init__
    self._setup_auth_table()
  File "E:\fuvarok_projekt\security\enhanced_auth.py", line 44, in _setup_auth_table
    self.db.execute_query(query)
  File "E:\fuvarok_projekt\database_handler.py", line 109, in execute_query
    self._conn.rollback()
    ^^^^^^^^^^
AttributeError: 'DatabaseHandler' object has no attribute '_conn'. Did you mean: 'conn'?
2025-01-02 10:17:43,304 - ERROR - Hiba: 'DatabaseHandler' object has no attribute '_conn'
Traceback (most recent call last):
  File "E:\fuvarok_projekt\database_handler.py", line 101, in execute_query
    cursor = self._conn.cursor()
             ^^^^^^^^^^
AttributeError: 'DatabaseHandler' object has no attribute '_conn'. Did you mean: 'conn'?

During handling of the above exception, another exception occurred:

Traceback (most recent call last):
  File "E:\fuvarok_projekt\run.py", line 16, in <module>
    window = FuvarAdminApp()
             ^^^^^^^^^^^^^^^
  File "E:\fuvarok_projekt\modified_main.py", line 30, in __init__
    self.auth_manager = EnhancedAuthManager(self.db)
                        ^^^^^^^^^^^^^^^^^^^^^^^^^^^^
  File "E:\fuvarok_projekt\security\enhanced_auth.py", line 17, in __init__
    self._setup_auth_table()
  File "E:\fuvarok_projekt\security\enhanced_auth.py", line 44, in _setup_auth_table
    self.db.execute_query(query)
  File "E:\fuvarok_projekt\database_handler.py", line 109, in execute_query
    self._conn.rollback()
    ^^^^^^^^^^
AttributeError: 'DatabaseHandler' object has no attribute '_conn'. Did you mean: 'conn'?
2025-01-02 10:18:49,757 - ERROR - Bejelentkezési hiba: no such column: locked_until
2025-01-02 10:21:29,956 - ERROR - Bejelentkezési hiba: no such column: locked_until
2025-01-02 10:22:44,926 - ERROR - Audit log hiba: 'DatabaseHandler' object has no attribute 'insert_record'
2025-01-02 11:01:10,698 - ERROR - Regisztrációs hiba: table users has no column named password_changed_at
2025-01-02 11:01:23,383 - ERROR - Bejelentkezési hiba: no such column: locked_until
2025-01-02 11:21:05,889 - ERROR - Query hiba: near "EXISTS": syntax error
2025-01-02 11:21:05,889 - WARNING - A `tachograph_type` oszlop hozzáadása nem sikerült: near "EXISTS": syntax error
2025-01-02 11:21:12,826 - ERROR - Query hiba: near "EXISTS": syntax error
2025-01-02 11:21:12,826 - WARNING - A `tachograph_type` oszlop hozzáadása nem sikerült: near "EXISTS": syntax error
2025-01-02 11:21:18,028 - ERROR - Query hiba: near "EXISTS": syntax error
2025-01-02 11:21:18,028 - WARNING - A `tachograph_type` oszlop hozzáadása nem sikerült: near "EXISTS": syntax error
2025-01-02 11:21:21,538 - ERROR - Query hiba: cannot commit transaction - SQL statements in progress
2025-01-02 11:21:30,634 - ERROR - Query hiba: table vehicles has no column named tachograph_type
2025-01-02 11:21:30,634 - ERROR - Insert hiba: table vehicles has no column named tachograph_type
2025-01-02 11:26:28,179 - ERROR - Query hiba: near "EXISTS": syntax error
2025-01-02 11:26:28,179 - WARNING - A `tachograph_type` oszlop hozzáadása nem sikerült: near "EXISTS": syntax error
2025-01-02 11:26:35,722 - ERROR - Query hiba: near "EXISTS": syntax error
2025-01-02 11:26:35,722 - WARNING - A `tachograph_type` oszlop hozzáadása nem sikerült: near "EXISTS": syntax error
2025-01-02 11:26:39,107 - ERROR - Query hiba: near "EXISTS": syntax error
2025-01-02 11:26:39,107 - WARNING - A `tachograph_type` oszlop hozzáadása nem sikerült: near "EXISTS": syntax error
2025-01-02 11:26:43,577 - ERROR - Query hiba: table vehicles has no column named tachograph_type
2025-01-02 11:26:43,577 - ERROR - Insert hiba: table vehicles has no column named tachograph_type
2025-01-02 11:32:05,008 - WARNING - A `tachograph_type` oszlop hozzáadása nem sikerült: 'NoneType' object is not iterable
2025-01-02 11:32:12,715 - WARNING - A `tachograph_type` oszlop hozzáadása nem sikerült: 'NoneType' object is not iterable
2025-01-02 11:32:15,995 - WARNING - A `tachograph_type` oszlop hozzáadása nem sikerült: 'NoneType' object is not iterable
2025-01-02 11:32:19,873 - ERROR - Query hiba: table vehicles has no column named tachograph_type
2025-01-02 11:32:19,873 - ERROR - Insert hiba: table vehicles has no column named tachograph_type
2025-01-02 11:40:05,382 - WARNING - A `tachograph_type` oszlop hozzáadása nem sikerült: 'NoneType' object is not iterable
2025-01-02 11:40:14,233 - WARNING - A `tachograph_type` oszlop hozzáadása nem sikerült: 'NoneType' object is not iterable
2025-01-02 11:40:17,602 - WARNING - A `tachograph_type` oszlop hozzáadása nem sikerült: 'NoneType' object is not iterable
2025-01-02 11:40:21,976 - ERROR - Query hiba: table vehicles has no column named tachograph_type
2025-01-02 11:40:21,976 - ERROR - Insert hiba: table vehicles has no column named tachograph_type
2025-01-02 11:43:37,474 - INFO - Minden szükséges tábla létrehozva vagy már létezik.
2025-01-02 11:43:44,744 - INFO - Minden szükséges tábla létrehozva vagy már létezik.
2025-01-02 11:44:17,603 - INFO - Minden szükséges tábla létrehozva vagy már létezik.
2025-01-02 11:44:33,965 - ERROR - Query hiba: cannot commit transaction - SQL statements in progress
2025-01-02 11:44:58,066 - ERROR - Query hiba: table vehicles has no column named tachograph_type
2025-01-02 11:44:58,066 - ERROR - Insert hiba: table vehicles has no column named tachograph_type
2025-01-02 11:58:29,894 - INFO - Minden szükséges tábla létrehozva vagy már létezik.
2025-01-02 11:58:36,806 - INFO - Minden szükséges tábla létrehozva vagy már létezik.
2025-01-02 11:58:41,730 - INFO - Minden szükséges tábla létrehozva vagy már létezik.
2025-01-02 11:58:45,540 - ERROR - Query hiba: cannot commit transaction - SQL statements in progress
2025-01-02 11:59:08,448 - ERROR - Query hiba: table vehicles has no column named tachograph_type
2025-01-02 11:59:08,448 - ERROR - Insert hiba: table vehicles has no column named tachograph_type
2025-01-02 12:01:37,709 - INFO - Minden szükséges tábla létrehozva vagy már létezik.
2025-01-02 12:01:44,174 - INFO - Minden szükséges tábla létrehozva vagy már létezik.
2025-01-02 12:01:47,682 - INFO - Minden szükséges tábla létrehozva vagy már létezik.
2025-01-02 12:01:52,523 - ERROR - Query hiba: cannot commit transaction - SQL statements in progress
2025-01-02 12:02:09,615 - ERROR - Query hiba: table vehicles has no column named tachograph_type
2025-01-02 12:02:09,615 - ERROR - Insert hiba: table vehicles has no column named tachograph_type
2025-01-02 12:05:20,110 - INFO - Minden szükséges tábla létrehozva vagy már létezik.
2025-01-02 12:05:20,110 - ERROR - A `vehicles` tábla nem létezik. Ellenõrizd a táblák inicializálását.
2025-01-02 12:05:26,044 - INFO - Minden szükséges tábla létrehozva vagy már létezik.
2025-01-02 12:05:26,044 - ERROR - A `vehicles` tábla nem létezik. Ellenõrizd a táblák inicializálását.
2025-01-02 12:05:29,706 - INFO - Minden szükséges tábla létrehozva vagy már létezik.
2025-01-02 12:05:29,706 - ERROR - A `vehicles` tábla nem létezik. Ellenõrizd a táblák inicializálását.
2025-01-02 12:05:35,635 - ERROR - SQL hiba: cannot commit transaction - SQL statements in progress
2025-01-02 12:05:42,135 - ERROR - SQL hiba: table vehicles has no column named tachograph_type
2025-01-02 12:06:01,969 - INFO - Minden szükséges tábla létrehozva vagy már létezik.
2025-01-02 12:06:01,969 - ERROR - A `vehicles` tábla nem létezik. Ellenõrizd a táblák inicializálását.
2025-01-02 12:06:15,939 - ERROR - SQL hiba: table vehicles has no column named tachograph_type
2025-01-02 12:30:11,127 - INFO - Minden szükséges tábla létrehozva vagy már létezik.
2025-01-02 12:30:18,084 - ERROR - Hiba: 'UIManager' object has no attribute 'save_button'
Traceback (most recent call last):
  File "E:\fuvarok_projekt\run.py", line 16, in <module>
    window = FuvarAdminApp()
             ^^^^^^^^^^^^^^^
  File "E:\fuvarok_projekt\modified_main.py", line 35, in __init__
    self.initManagers()
  File "E:\fuvarok_projekt\modified_main.py", line 67, in initManagers
    self.ui_manager = UIManager(self)
                      ^^^^^^^^^^^^^^^
  File "E:\fuvarok_projekt\ui_manager.py", line 12, in __init__
    self.save_button.clicked.connect(self.save_vehicle)
    ^^^^^^^^^^^^^^^^
AttributeError: 'UIManager' object has no attribute 'save_button'
2025-01-02 12:38:46,784 - INFO - Minden szükséges tábla létrehozva vagy már létezik.
2025-01-02 12:38:53,891 - INFO - Minden szükséges tábla létrehozva vagy már létezik.
2025-01-02 12:38:53,904 - INFO - Minden szükséges tábla létrehozva vagy már létezik.
2025-01-02 12:39:07,187 - ERROR - Hiba: 'UIManager' object has no attribute 'styles'
Traceback (most recent call last):
  File "E:\fuvarok_projekt\run.py", line 16, in <module>
    window = FuvarAdminApp()
             ^^^^^^^^^^^^^^^
  File "E:\fuvarok_projekt\modified_main.py", line 36, in __init__
    self.initUI()
  File "E:\fuvarok_projekt\modified_main.py", line 85, in initUI
    top_frame = self.ui_manager.createTopFrame()
                ^^^^^^^^^^^^^^^^^^^^^^^^^^^^^^^^
  File "E:\fuvarok_projekt\ui_manager.py", line 116, in createTopFrame
    top_frame.setStyleSheet(self.styles['main_frame'])
                            ^^^^^^^^^^^
AttributeError: 'UIManager' object has no attribute 'styles'
2025-01-02 12:54:58,956 - INFO - Minden szükséges tábla létrehozva vagy már létezik.
2025-01-02 12:55:06,126 - INFO - Adatbázis kapcsolat létrejött.
2025-01-02 12:55:06,126 - INFO - Query sikeres: 
                CREATE TABLE IF NOT EXISTS vehicles (
                    id INTEGER PRIMARY KEY AUTOINCREMENT,
                    license_plate TEXT NOT NULL,
                    type TEXT,
                    brand TEXT,
                    model TEXT,
                    manufacture_year INTEGER,
                    tachograph_type TEXT
                );
                
2025-01-02 12:55:06,126 - INFO - Szükséges táblák létrehozva vagy már léteznek.
2025-01-02 12:55:06,126 - ERROR - Hiba: 'FuvarAdminApp' object has no attribute 'setColumnCount'
Traceback (most recent call last):
  File "E:\fuvarok_projekt\run.py", line 16, in <module>
    window = FuvarAdminApp()
             ^^^^^^^^^^^^^^^
  File "E:\fuvarok_projekt\modified_main.py", line 35, in __init__
    self.initManagers()
  File "E:\fuvarok_projekt\modified_main.py", line 67, in initManagers
    self.ui_manager = UIManager(self)
                      ^^^^^^^^^^^^^^^
  File "E:\fuvarok_projekt\ui_manager.py", line 101, in __init__
    self.setup_ui()
  File "E:\fuvarok_projekt\ui_manager.py", line 108, in setup_ui
    self.vehicle_table.setColumnCount(7)
    ^^^^^^^^^^^^^^^^^^^^^^^^^^^^^^^^^
AttributeError: 'FuvarAdminApp' object has no attribute 'setColumnCount'
2025-01-02 12:55:06,173 - INFO - Adatbázis kapcsolat lezárva.
2025-01-02 19:22:25,063 - ERROR - Hiba: unrecognized token: "#"
Traceback (most recent call last):
  File "E:\fuvarok_projekt\run.py", line 16, in <module>
    window = FuvarAdminApp()
             ^^^^^^^^^^^^^^^
  File "E:\fuvarok_projekt\modified_main.py", line 35, in __init__
    self.initManagers()
  File "E:\fuvarok_projekt\modified_main.py", line 68, in initManagers
    self.database_manager = DatabaseManager(self)
                            ^^^^^^^^^^^^^^^^^^^^^
  File "E:\fuvarok_projekt\database_manager.py", line 30, in __init__
    self.setupDatabase()
  File "E:\fuvarok_projekt\database_manager.py", line 55, in setupDatabase
    self.db.execute_query('''
  File "E:\fuvarok_projekt\database_handler.py", line 22, in execute_query
    cursor.execute(query, params)
sqlite3.OperationalError: unrecognized token: "#"
2025-01-02 20:20:42,394 - ERROR - Hiba: 'DatabaseManager' object has no attribute 'saveVehicleChanges'
Traceback (most recent call last):
  File "E:\fuvarok_projekt\run.py", line 16, in <module>
    window = FuvarAdminApp()
             ^^^^^^^^^^^^^^^
  File "E:\fuvarok_projekt\modified_main.py", line 35, in __init__
    self.initManagers()
  File "E:\fuvarok_projekt\modified_main.py", line 68, in initManagers
    self.database_manager = DatabaseManager(self)
                            ^^^^^^^^^^^^^^^^^^^^^
  File "E:\fuvarok_projekt\database_manager.py", line 30, in __init__
    self.initUI()
  File "E:\fuvarok_projekt\database_manager.py", line 41, in initUI
    tabs.addTab(self.createVehiclesTab(), "Gépjármûvek")
                ^^^^^^^^^^^^^^^^^^^^^^^^
  File "E:\fuvarok_projekt\database_manager.py", line 432, in createVehiclesTab
    save_btn.clicked.connect(self.saveVehicleChanges)
                             ^^^^^^^^^^^^^^^^^^^^^^^
AttributeError: 'DatabaseManager' object has no attribute 'saveVehicleChanges'. Did you mean: 'onVehicleChanged'?
2025-01-02 20:23:19,073 - ERROR - Hiba: 'DatabaseManager' object has no attribute 'deleteVehicle'
Traceback (most recent call last):
  File "E:\fuvarok_projekt\run.py", line 16, in <module>
    window = FuvarAdminApp()
             ^^^^^^^^^^^^^^^
  File "E:\fuvarok_projekt\modified_main.py", line 35, in __init__
    self.initManagers()
  File "E:\fuvarok_projekt\modified_main.py", line 68, in initManagers
    self.database_manager = DatabaseManager(self)
                            ^^^^^^^^^^^^^^^^^^^^^
  File "E:\fuvarok_projekt\database_manager.py", line 30, in __init__
    self.initUI()
  File "E:\fuvarok_projekt\database_manager.py", line 41, in initUI
    tabs.addTab(self.createVehiclesTab(), "Gépjármûvek")
                ^^^^^^^^^^^^^^^^^^^^^^^^
  File "E:\fuvarok_projekt\database_manager.py", line 433, in createVehiclesTab
    delete_btn.clicked.connect(self.deleteVehicle)
                               ^^^^^^^^^^^^^^^^^^
AttributeError: 'DatabaseManager' object has no attribute 'deleteVehicle'
2025-01-02 20:25:39,360 - ERROR - SQL végrehajtási hiba: table vehicles has no column named tachograph_type
2025-01-02 20:25:39,360 - ERROR - Beszúrási hiba: table vehicles has no column named tachograph_type
2025-01-02 20:37:09,965 - ERROR - Hiba: 'DatabaseManager' object has no attribute 'execute_query'
Traceback (most recent call last):
  File "E:\fuvarok_projekt\run.py", line 16, in <module>
    window = FuvarAdminApp()
             ^^^^^^^^^^^^^^^
  File "E:\fuvarok_projekt\modified_main.py", line 35, in __init__
    self.initManagers()
  File "E:\fuvarok_projekt\modified_main.py", line 68, in initManagers
    self.database_manager = DatabaseManager(self)
                            ^^^^^^^^^^^^^^^^^^^^^
  File "E:\fuvarok_projekt\database_manager.py", line 30, in __init__
    self.setupDatabase()
  File "E:\fuvarok_projekt\database_manager.py", line 68, in setupDatabase
    self.execute_query('''
    ^^^^^^^^^^^^^^^^^^
AttributeError: 'DatabaseManager' object has no attribute 'execute_query'
2025-01-02 20:41:16,931 - ERROR - Hiba: 'DatabaseManager' object has no attribute 'deleteFactory'
Traceback (most recent call last):
  File "E:\fuvarok_projekt\run.py", line 16, in <module>
    window = FuvarAdminApp()
             ^^^^^^^^^^^^^^^
  File "E:\fuvarok_projekt\modified_main.py", line 35, in __init__
    self.initManagers()
  File "E:\fuvarok_projekt\modified_main.py", line 68, in initManagers
    self.database_manager = DatabaseManager(self)
                            ^^^^^^^^^^^^^^^^^^^^^
  File "E:\fuvarok_projekt\database_manager.py", line 31, in __init__
    self.initUI()
  File "E:\fuvarok_projekt\database_manager.py", line 41, in initUI
    tabs.addTab(self.createFactoriesTab(), "Gyárak")
                ^^^^^^^^^^^^^^^^^^^^^^^^^
  File "E:\fuvarok_projekt\database_manager.py", line 789, in createFactoriesTab
    delete_factory_btn.clicked.connect(self.deleteFactory)
                                       ^^^^^^^^^^^^^^^^^^
AttributeError: 'DatabaseManager' object has no attribute 'deleteFactory'. Did you mean: 'deleteLater'?
2025-01-02 20:46:30,209 - ERROR - SQL végrehajtási hiba: cannot commit transaction - SQL statements in progress
2025-01-02 20:46:46,948 - ERROR - SQL végrehajtási hiba: table vehicles has no column named tachograph_type
2025-01-02 20:46:46,948 - ERROR - Beszúrási hiba: table vehicles has no column named tachograph_type
2025-01-02 20:59:25,134 - ERROR - Hiba: 'DatabaseManager' object has no attribute 'vehicle_table'
Traceback (most recent call last):
  File "E:\fuvarok_projekt\run.py", line 16, in <module>
    window = FuvarAdminApp()
             ^^^^^^^^^^^^^^^
  File "E:\fuvarok_projekt\modified_main.py", line 35, in __init__
    self.initManagers()
  File "E:\fuvarok_projekt\modified_main.py", line 68, in initManagers
    self.database_manager = DatabaseManager(self)
                            ^^^^^^^^^^^^^^^^^^^^^
  File "E:\fuvarok_projekt\database_manager.py", line 31, in __init__
    self.initUI()
  File "E:\fuvarok_projekt\database_manager.py", line 49, in initUI
    self.setupConnections()
  File "E:\fuvarok_projekt\database_manager.py", line 60, in setupConnections
    self.vehicle_table.itemClicked.connect(self.onVehicleSelected)
    ^^^^^^^^^^^^^^^^^^
AttributeError: 'DatabaseManager' object has no attribute 'vehicle_table'. Did you mean: 'vehicles_table'?
2025-01-02 21:01:16,009 - ERROR - Hiba: 'DatabaseManager' object has no attribute 'add_vehicle_btn'
Traceback (most recent call last):
  File "E:\fuvarok_projekt\run.py", line 16, in <module>
    window = FuvarAdminApp()
             ^^^^^^^^^^^^^^^
  File "E:\fuvarok_projekt\modified_main.py", line 35, in __init__
    self.initManagers()
  File "E:\fuvarok_projekt\modified_main.py", line 68, in initManagers
    self.database_manager = DatabaseManager(self)
                            ^^^^^^^^^^^^^^^^^^^^^
  File "E:\fuvarok_projekt\database_manager.py", line 31, in __init__
    self.initUI()
  File "E:\fuvarok_projekt\database_manager.py", line 49, in initUI
    self.setupConnections()
  File "E:\fuvarok_projekt\database_manager.py", line 60, in setupConnections
    self.add_vehicle_btn.clicked.connect(self.addVehicle)
    ^^^^^^^^^^^^^^^^^^^^
AttributeError: 'DatabaseManager' object has no attribute 'add_vehicle_btn'
2025-01-02 21:06:43,099 - ERROR - Hiba: 'DatabaseManager' object has no attribute 'vehicle_table'
Traceback (most recent call last):
  File "E:\fuvarok_projekt\run.py", line 16, in <module>
    window = FuvarAdminApp()
             ^^^^^^^^^^^^^^^
  File "E:\fuvarok_projekt\modified_main.py", line 35, in __init__
    self.initManagers()
  File "E:\fuvarok_projekt\modified_main.py", line 68, in initManagers
    self.database_manager = DatabaseManager(self)
                            ^^^^^^^^^^^^^^^^^^^^^
  File "E:\fuvarok_projekt\database_manager.py", line 31, in __init__
    self.initUI()
  File "E:\fuvarok_projekt\database_manager.py", line 49, in initUI
    self.setupConnections()
  File "E:\fuvarok_projekt\database_manager.py", line 59, in setupConnections
    self.vehicle_table.itemClicked.connect(self.onVehicleSelected)
    ^^^^^^^^^^^^^^^^^^
AttributeError: 'DatabaseManager' object has no attribute 'vehicle_table'. Did you mean: 'vehicles_table'?
2025-01-02 21:08:12,160 - ERROR - Hiba: 'DatabaseManager' object has no attribute 'vehicle_table'
Traceback (most recent call last):
  File "E:\fuvarok_projekt\run.py", line 16, in <module>
    window = FuvarAdminApp()
             ^^^^^^^^^^^^^^^
  File "E:\fuvarok_projekt\modified_main.py", line 35, in __init__
    self.initManagers()
  File "E:\fuvarok_projekt\modified_main.py", line 68, in initManagers
    self.database_manager = DatabaseManager(self)
                            ^^^^^^^^^^^^^^^^^^^^^
  File "E:\fuvarok_projekt\database_manager.py", line 31, in __init__
    self.initUI()
  File "E:\fuvarok_projekt\database_manager.py", line 49, in initUI
    self.setupConnections()
  File "E:\fuvarok_projekt\database_manager.py", line 59, in setupConnections
    self.vehicle_table.itemClicked.connect(self.onVehicleSelected)
    ^^^^^^^^^^^^^^^^^^
AttributeError: 'DatabaseManager' object has no attribute 'vehicle_table'. Did you mean: 'vehicles_table'?
2025-01-02 21:09:07,929 - ERROR - Hiba: 'DatabaseManager' object has no attribute 'drivers_table'
Traceback (most recent call last):
  File "E:\fuvarok_projekt\run.py", line 16, in <module>
    window = FuvarAdminApp()
             ^^^^^^^^^^^^^^^
  File "E:\fuvarok_projekt\modified_main.py", line 35, in __init__
    self.initManagers()
  File "E:\fuvarok_projekt\modified_main.py", line 68, in initManagers
    self.database_manager = DatabaseManager(self)
                            ^^^^^^^^^^^^^^^^^^^^^
  File "E:\fuvarok_projekt\database_manager.py", line 31, in __init__
    self.initUI()
  File "E:\fuvarok_projekt\database_manager.py", line 49, in initUI
    self.setupConnections()
  File "E:\fuvarok_projekt\database_manager.py", line 53, in setupConnections
    self.drivers_table.itemClicked.connect(self.onDriverSelected)
    ^^^^^^^^^^^^^^^^^^
AttributeError: 'DatabaseManager' object has no attribute 'drivers_table'. Did you mean: 'driver_table'?
2025-01-02 21:11:18,115 - ERROR - Hiba: 'DatabaseManager' object has no attribute 'add_drivers_btn'
Traceback (most recent call last):
  File "E:\fuvarok_projekt\run.py", line 16, in <module>
    window = FuvarAdminApp()
             ^^^^^^^^^^^^^^^
  File "E:\fuvarok_projekt\modified_main.py", line 35, in __init__
    self.initManagers()
  File "E:\fuvarok_projekt\modified_main.py", line 68, in initManagers
    self.database_manager = DatabaseManager(self)
                            ^^^^^^^^^^^^^^^^^^^^^
  File "E:\fuvarok_projekt\database_manager.py", line 31, in __init__
    self.initUI()
  File "E:\fuvarok_projekt\database_manager.py", line 49, in initUI
    self.setupConnections()
  File "E:\fuvarok_projekt\database_manager.py", line 54, in setupConnections
    self.add_drivers_btn.clicked.connect(self.addDriver)
    ^^^^^^^^^^^^^^^^^^^^
AttributeError: 'DatabaseManager' object has no attribute 'add_drivers_btn'. Did you mean: 'add_driver_btn'?
2025-01-02 21:13:14,922 - ERROR - Hiba: 'DatabaseManager' object has no attribute 'vehicle_table'
Traceback (most recent call last):
  File "E:\fuvarok_projekt\run.py", line 16, in <module>
    window = FuvarAdminApp()
             ^^^^^^^^^^^^^^^
  File "E:\fuvarok_projekt\modified_main.py", line 35, in __init__
    self.initManagers()
  File "E:\fuvarok_projekt\modified_main.py", line 68, in initManagers
    self.database_manager = DatabaseManager(self)
                            ^^^^^^^^^^^^^^^^^^^^^
  File "E:\fuvarok_projekt\database_manager.py", line 31, in __init__
    self.initUI()
  File "E:\fuvarok_projekt\database_manager.py", line 49, in initUI
    self.setupConnections()
  File "E:\fuvarok_projekt\database_manager.py", line 59, in setupConnections
    self.vehicle_table.itemClicked.connect(self.onVehicleSelected)
    ^^^^^^^^^^^^^^^^^^
AttributeError: 'DatabaseManager' object has no attribute 'vehicle_table'. Did you mean: 'vehicles_table'?
2025-01-02 21:14:23,381 - ERROR - Hiba: 'DatabaseManager' object has no attribute 'drivers_table'
Traceback (most recent call last):
  File "E:\fuvarok_projekt\run.py", line 16, in <module>
    window = FuvarAdminApp()
             ^^^^^^^^^^^^^^^
  File "E:\fuvarok_projekt\modified_main.py", line 35, in __init__
    self.initManagers()
  File "E:\fuvarok_projekt\modified_main.py", line 68, in initManagers
    self.database_manager = DatabaseManager(self)
                            ^^^^^^^^^^^^^^^^^^^^^
  File "E:\fuvarok_projekt\database_manager.py", line 31, in __init__
    self.initUI()
  File "E:\fuvarok_projekt\database_manager.py", line 49, in initUI
    self.setupConnections()
  File "E:\fuvarok_projekt\database_manager.py", line 53, in setupConnections
    self.drivers_table.itemClicked.connect(self.onDriverSelected)
    ^^^^^^^^^^^^^^^^^^
AttributeError: 'DatabaseManager' object has no attribute 'drivers_table'. Did you mean: 'driver_table'?
2025-01-02 21:16:47,907 - ERROR - Hiba: 'DatabaseManager' object has no attribute 'vehicle_table'
Traceback (most recent call last):
  File "E:\fuvarok_projekt\run.py", line 16, in <module>
    window = FuvarAdminApp()
             ^^^^^^^^^^^^^^^
  File "E:\fuvarok_projekt\modified_main.py", line 35, in __init__
    self.initManagers()
  File "E:\fuvarok_projekt\modified_main.py", line 68, in initManagers
    self.database_manager = DatabaseManager(self)
                            ^^^^^^^^^^^^^^^^^^^^^
  File "E:\fuvarok_projekt\database_manager.py", line 31, in __init__
    self.initUI()
  File "E:\fuvarok_projekt\database_manager.py", line 49, in initUI
    self.setupConnections()
  File "E:\fuvarok_projekt\database_manager.py", line 59, in setupConnections
    self.vehicle_table.itemClicked.connect(self.onVehicleSelected)
    ^^^^^^^^^^^^^^^^^^
AttributeError: 'DatabaseManager' object has no attribute 'vehicle_table'. Did you mean: 'vehicles_table'?
2025-01-03 06:05:49,504 - ERROR - Hiba: 'DatabaseManager' object has no attribute 'vehicle_table'
Traceback (most recent call last):
  File "E:\fuvarok_projekt\run.py", line 16, in <module>
    window = FuvarAdminApp()
             ^^^^^^^^^^^^^^^
  File "E:\fuvarok_projekt\modified_main.py", line 35, in __init__
    self.initManagers()
  File "E:\fuvarok_projekt\modified_main.py", line 68, in initManagers
    self.database_manager = DatabaseManager(self)
                            ^^^^^^^^^^^^^^^^^^^^^
  File "E:\fuvarok_projekt\database_manager.py", line 31, in __init__
    self.initUI()
  File "E:\fuvarok_projekt\database_manager.py", line 49, in initUI
    self.setupConnections()
  File "E:\fuvarok_projekt\database_manager.py", line 59, in setupConnections
    self.vehicle_table.itemClicked.connect(self.onVehicleSelected)
    ^^^^^^^^^^^^^^^^^^
AttributeError: 'DatabaseManager' object has no attribute 'vehicle_table'. Did you mean: 'vehicles_table'?
2025-01-03 06:15:14,638 - ERROR - Hiba: 'DatabaseManager' object has no attribute 'add_vehicle_btn'
Traceback (most recent call last):
  File "E:\fuvarok_projekt\run.py", line 16, in <module>
    window = FuvarAdminApp()
             ^^^^^^^^^^^^^^^
  File "E:\fuvarok_projekt\modified_main.py", line 35, in __init__
    self.initManagers()
  File "E:\fuvarok_projekt\modified_main.py", line 68, in initManagers
    self.database_manager = DatabaseManager(self)
                            ^^^^^^^^^^^^^^^^^^^^^
  File "E:\fuvarok_projekt\database_manager.py", line 31, in __init__
    self.initUI()
  File "E:\fuvarok_projekt\database_manager.py", line 49, in initUI
    self.setupConnections()
  File "E:\fuvarok_projekt\database_manager.py", line 60, in setupConnections
    self.add_vehicle_btn.clicked.connect(self.addVehicle)
    ^^^^^^^^^^^^^^^^^^^^
AttributeError: 'DatabaseManager' object has no attribute 'add_vehicle_btn'
2025-01-03 06:42:28,361 - ERROR - SQL végrehajtási hiba: no such column: tachograph
2025-01-03 06:42:38,614 - ERROR - SQL végrehajtási hiba: no such column: tachograph
2025-01-03 06:48:17,001 - ERROR - SQL végrehajtási hiba: no such column: tachograph
2025-01-03 06:48:18,549 - ERROR - SQL végrehajtási hiba: no such column: tachograph
2025-01-03 08:06:25,079 - ERROR - SQL végrehajtási hiba: no such column: tachograph
2025-01-03 08:06:28,636 - ERROR - SQL végrehajtási hiba: no such column: tachograph
2025-01-03 08:06:52,823 - ERROR - SQL végrehajtási hiba: no such column: tachograph
2025-01-03 08:06:56,364 - ERROR - SQL végrehajtási hiba: no such column: tachograph
2025-01-03 08:08:05,658 - ERROR - SQL végrehajtási hiba: FOREIGN KEY constraint failed
2025-01-03 08:08:17,479 - ERROR - SQL végrehajtási hiba: FOREIGN KEY constraint failed
2025-01-03 08:09:14,631 - ERROR - SQL végrehajtási hiba: FOREIGN KEY constraint failed
2025-01-03 08:10:48,351 - ERROR - SQL végrehajtási hiba: no such column: tachograph
2025-01-03 08:10:49,852 - ERROR - SQL végrehajtási hiba: no such column: tachograph
